2023-05-16 10:29:50,068 INFO    MainThread:14644 [wandb_setup.py:_flush():76] Configure stats pid to 14644
2023-05-16 10:29:50,069 INFO    MainThread:14644 [wandb_setup.py:_flush():76] Loading settings from C:\Users\gaura\.config\wandb\settings
2023-05-16 10:29:50,069 INFO    MainThread:14644 [wandb_setup.py:_flush():76] Loading settings from c:\Users\gaura\PycharmProjects\scientificProject\wandb\settings
2023-05-16 10:29:50,069 INFO    MainThread:14644 [wandb_setup.py:_flush():76] Loading settings from environment variables: {'entity': 'cs22m045', 'project': 'aksharantar_without_attention_1', 'root_dir': 'c:\\Users\\gaura\\PycharmProjects\\scientificProject', 'run_id': '3iwp0q0c', 'sweep_param_path': 'c:\\Users\\gaura\\PycharmProjects\\scientificProject\\wandb\\sweep-pdmj2vl5\\config-3iwp0q0c.yaml', 'sweep_id': 'pdmj2vl5'}
2023-05-16 10:29:50,104 INFO    MainThread:14644 [wandb_setup.py:_flush():76] Applying setup settings: {'_disable_service': False}
2023-05-16 10:29:50,104 INFO    MainThread:14644 [wandb_setup.py:_flush():76] Inferring run settings from compute environment: {'program': '<python with no main file>'}
2023-05-16 10:29:50,106 INFO    MainThread:14644 [wandb_init.py:_log_setup():506] Logging user logs to c:\Users\gaura\PycharmProjects\scientificProject\wandb\run-20230516_102950-3iwp0q0c\logs\debug.log
2023-05-16 10:29:50,106 INFO    MainThread:14644 [wandb_init.py:_log_setup():507] Logging internal logs to c:\Users\gaura\PycharmProjects\scientificProject\wandb\run-20230516_102950-3iwp0q0c\logs\debug-internal.log
2023-05-16 10:29:50,107 INFO    MainThread:14644 [wandb_init.py:init():546] calling init triggers
2023-05-16 10:29:50,107 INFO    MainThread:14644 [wandb_init.py:init():552] wandb.init called with sweep_config: {'batch_size': 128, 'bidirectional': False, 'cell_type': 'LSTM', 'dropout': 0.4, 'embedding_size': 512, 'hidden_size': 512, 'learning_rate': 0.001, 'num_layers': 2}
config: {}
2023-05-16 10:29:50,107 INFO    MainThread:14644 [wandb_init.py:init():568] re-initializing run, found existing run on stack: 3iwp0q0c
2023-05-16 10:29:50,117 INFO    MainThread:14644 [wandb_run.py:_finish():1854] finishing run cs22m045/aksharantar_without_attention_1/3iwp0q0c
2023-05-16 10:29:50,119 INFO    MainThread:14644 [jupyter.py:save_history():445] not saving jupyter history
2023-05-16 10:29:50,119 INFO    MainThread:14644 [jupyter.py:save_ipynb():373] not saving jupyter notebook
2023-05-16 10:29:50,119 INFO    MainThread:14644 [wandb_init.py:_jupyter_teardown():434] cleaning up jupyter logic
2023-05-16 10:29:50,120 INFO    MainThread:14644 [wandb_run.py:_atexit_cleanup():2083] got exitcode: 0
2023-05-16 10:29:50,120 INFO    MainThread:14644 [wandb_run.py:_restore():2066] restore
2023-05-16 10:29:50,121 INFO    MainThread:14644 [wandb_run.py:_restore():2072] restore done
2023-05-16 10:29:55,178 INFO    MainThread:14644 [wandb_run.py:_footer_history_summary_info():3422] rendering history
2023-05-16 10:29:55,178 INFO    MainThread:14644 [wandb_run.py:_footer_history_summary_info():3454] rendering summary
2023-05-16 10:29:55,188 INFO    MainThread:14644 [wandb_run.py:_footer_sync_info():3380] logging synced files
2023-05-16 10:29:55,210 INFO    MainThread:14644 [wandb_init.py:init():602] starting backend
2023-05-16 10:29:55,211 INFO    MainThread:14644 [wandb_init.py:init():606] setting up manager
2023-05-16 10:29:55,231 INFO    MainThread:14644 [backend.py:_multiprocessing_setup():106] multiprocessing start_methods=spawn, using: spawn
2023-05-16 10:29:55,248 INFO    MainThread:14644 [wandb_init.py:init():613] backend started and connected
2023-05-16 10:29:55,278 INFO    MainThread:14644 [wandb_run.py:_config_callback():1251] config_cb None None {'batch_size': 128, 'bidirectional': False, 'cell_type': 'LSTM', 'dropout': 0.4, 'embedding_size': 512, 'hidden_size': 512, 'learning_rate': 0.001, 'num_layers': 2}
2023-05-16 10:29:55,281 INFO    MainThread:14644 [wandb_run.py:_label_probe_notebook():1204] probe notebook
2023-05-16 10:29:55,281 INFO    MainThread:14644 [wandb_run.py:_label_probe_notebook():1214] Unable to probe notebook: 'NoneType' object has no attribute 'get'
2023-05-16 10:29:55,282 INFO    MainThread:14644 [wandb_init.py:init():701] updated telemetry
2023-05-16 10:29:55,417 INFO    MainThread:14644 [wandb_init.py:init():741] communicating run to backend with 60.0 second timeout
2023-05-16 10:29:56,916 INFO    MainThread:14644 [wandb_run.py:_on_init():2133] communicating current version
2023-05-16 10:29:56,996 INFO    MainThread:14644 [wandb_run.py:_on_init():2142] got version response upgrade_message: "wandb version 0.15.2 is available!  To upgrade, please run:\n $ pip install wandb --upgrade"

2023-05-16 10:29:56,996 INFO    MainThread:14644 [wandb_init.py:init():789] starting run threads in backend
2023-05-16 10:29:57,229 INFO    MainThread:14644 [wandb_run.py:_console_start():2114] atexit reg
2023-05-16 10:29:57,229 INFO    MainThread:14644 [wandb_run.py:_redirect():1969] redirect: 3
2023-05-16 10:29:57,229 INFO    MainThread:14644 [wandb_run.py:_redirect():2034] Wrapping output streams.
2023-05-16 10:29:57,230 INFO    MainThread:14644 [wandb_run.py:_redirect():2059] Redirects installed.
2023-05-16 10:29:57,230 INFO    MainThread:14644 [wandb_init.py:init():831] run started, returning control to user process
2023-05-16 10:47:35,005 INFO    MainThread:14644 [pyagent.py:run():314] Starting sweep agent: entity=None, project=None, count=15
2023-05-16 10:47:44,682 WARNING MsgRouterThr:14644 [router.py:message_loop():77] message_loop has been closed
2023-05-16 10:47:46,000 ERROR   Thread-85 (_run_job):14644 [jupyter.py:notebook_metadata():224] Failed to detect the name of this notebook, you can set it manually with the WANDB_NOTEBOOK_NAME environment variable to enable code saving.
2023-05-16 10:47:52,163 INFO    Thread-85 (_run_job):14644 [wandb_setup.py:_flush():76] Configure stats pid to 14644
2023-05-16 10:47:52,165 INFO    Thread-85 (_run_job):14644 [wandb_setup.py:_flush():76] Loading settings from C:\Users\gaura\.config\wandb\settings
2023-05-16 10:47:52,165 INFO    Thread-85 (_run_job):14644 [wandb_setup.py:_flush():76] Loading settings from c:\Users\gaura\PycharmProjects\scientificProject\wandb\settings
2023-05-16 10:47:52,165 INFO    Thread-85 (_run_job):14644 [wandb_setup.py:_flush():76] Loading settings from environment variables: {'entity': 'cs22m045', 'project': 'aksharantar_without_attention_1', 'root_dir': 'c:\\Users\\gaura\\PycharmProjects\\scientificProject', 'sweep_id': 'hh3vahjz', 'run_id': '6ql60a7c', 'sweep_param_path': 'c:\\Users\\gaura\\PycharmProjects\\scientificProject\\wandb\\sweep-hh3vahjz\\config-6ql60a7c.yaml'}
2023-05-16 10:47:52,172 INFO    Thread-85 (_run_job):14644 [wandb_setup.py:_flush():76] Applying setup settings: {'_disable_service': False}
2023-05-16 10:47:52,173 INFO    Thread-85 (_run_job):14644 [wandb_setup.py:_flush():76] Inferring run settings from compute environment: {'program': '<python with no main file>'}
2023-05-16 10:47:52,173 INFO    Thread-85 (_run_job):14644 [wandb_init.py:_log_setup():506] Logging user logs to c:\Users\gaura\PycharmProjects\scientificProject\wandb\run-20230516_104752-6ql60a7c\logs\debug.log
2023-05-16 10:47:52,173 INFO    Thread-85 (_run_job):14644 [wandb_init.py:_log_setup():507] Logging internal logs to c:\Users\gaura\PycharmProjects\scientificProject\wandb\run-20230516_104752-6ql60a7c\logs\debug-internal.log
2023-05-16 10:47:52,173 INFO    Thread-85 (_run_job):14644 [wandb_init.py:_jupyter_setup():452] configuring jupyter hooks <wandb.sdk.wandb_init._WandbInit object at 0x000001FF2D502850>
2023-05-16 10:47:52,173 INFO    Thread-85 (_run_job):14644 [wandb_init.py:init():546] calling init triggers
2023-05-16 10:47:52,174 INFO    Thread-85 (_run_job):14644 [wandb_init.py:init():552] wandb.init called with sweep_config: {'batch_size': 128, 'bidirectional': False, 'cell_type': 'GRU', 'dec_dropout': 0.4, 'embedding_size': 512, 'enc_dropout': 0.4, 'hidden_size': 256, 'learning_rate': 0.1, 'num_epochs': 15, 'num_layers': 1}
config: {}
2023-05-16 10:47:52,175 INFO    Thread-85 (_run_job):14644 [wandb_init.py:init():602] starting backend
2023-05-16 10:47:52,175 INFO    Thread-85 (_run_job):14644 [wandb_init.py:init():606] setting up manager
2023-05-16 10:47:52,184 INFO    Thread-85 (_run_job):14644 [backend.py:_multiprocessing_setup():106] multiprocessing start_methods=spawn, using: spawn
2023-05-16 10:47:52,213 INFO    Thread-85 (_run_job):14644 [wandb_init.py:init():613] backend started and connected
2023-05-16 10:47:52,243 INFO    Thread-85 (_run_job):14644 [wandb_run.py:_config_callback():1251] config_cb None None {'batch_size': 128, 'bidirectional': False, 'cell_type': 'GRU', 'dec_dropout': 0.4, 'embedding_size': 512, 'enc_dropout': 0.4, 'hidden_size': 256, 'learning_rate': 0.1, 'num_epochs': 15, 'num_layers': 1}
2023-05-16 10:47:52,243 INFO    Thread-85 (_run_job):14644 [wandb_run.py:_label_probe_notebook():1204] probe notebook
2023-05-16 10:47:52,247 INFO    Thread-85 (_run_job):14644 [wandb_run.py:_label_probe_notebook():1214] Unable to probe notebook: 'NoneType' object has no attribute 'get'
2023-05-16 10:47:52,247 INFO    Thread-85 (_run_job):14644 [wandb_init.py:init():701] updated telemetry
2023-05-16 10:47:52,574 INFO    Thread-85 (_run_job):14644 [wandb_init.py:init():741] communicating run to backend with 60.0 second timeout
2023-05-16 10:47:53,722 INFO    Thread-85 (_run_job):14644 [wandb_run.py:_on_init():2133] communicating current version
2023-05-16 10:47:53,844 INFO    Thread-85 (_run_job):14644 [wandb_run.py:_on_init():2142] got version response upgrade_message: "wandb version 0.15.2 is available!  To upgrade, please run:\n $ pip install wandb --upgrade"

2023-05-16 10:47:53,844 INFO    Thread-85 (_run_job):14644 [wandb_init.py:init():789] starting run threads in backend
2023-05-16 10:47:54,262 INFO    Thread-85 (_run_job):14644 [wandb_run.py:_console_start():2114] atexit reg
2023-05-16 10:47:54,262 INFO    Thread-85 (_run_job):14644 [wandb_run.py:_redirect():1969] redirect: 3
2023-05-16 10:47:54,264 INFO    Thread-85 (_run_job):14644 [wandb_run.py:_redirect():2034] Wrapping output streams.
2023-05-16 10:47:54,264 INFO    Thread-85 (_run_job):14644 [wandb_run.py:_redirect():2059] Redirects installed.
2023-05-16 10:47:54,266 INFO    Thread-85 (_run_job):14644 [wandb_init.py:init():831] run started, returning control to user process
2023-05-16 10:47:54,266 INFO    Thread-85 (_run_job):14644 [wandb_run.py:_finish():1854] finishing run cs22m045/aksharantar_without_attention_1/6ql60a7c
2023-05-16 10:47:54,269 INFO    Thread-85 (_run_job):14644 [jupyter.py:save_history():445] not saving jupyter history
2023-05-16 10:47:54,269 INFO    Thread-85 (_run_job):14644 [jupyter.py:save_ipynb():373] not saving jupyter notebook
2023-05-16 10:47:54,269 INFO    Thread-85 (_run_job):14644 [wandb_init.py:_jupyter_teardown():434] cleaning up jupyter logic
2023-05-16 10:47:54,269 INFO    Thread-85 (_run_job):14644 [wandb_run.py:_atexit_cleanup():2083] got exitcode: 1
2023-05-16 10:47:54,269 INFO    Thread-85 (_run_job):14644 [wandb_run.py:_restore():2066] restore
2023-05-16 10:47:54,269 INFO    Thread-85 (_run_job):14644 [wandb_run.py:_restore():2072] restore done
2023-05-16 10:47:59,605 INFO    Thread-85 (_run_job):14644 [wandb_run.py:_footer_history_summary_info():3422] rendering history
2023-05-16 10:47:59,605 INFO    Thread-85 (_run_job):14644 [wandb_run.py:_footer_history_summary_info():3454] rendering summary
2023-05-16 10:47:59,612 INFO    Thread-85 (_run_job):14644 [wandb_run.py:_footer_sync_info():3380] logging synced files
2023-05-16 10:47:59,618 ERROR   MainThread:14644 [pyagent.py:_run_jobs_from_queue():226] Run 6ql60a7c errored: UnboundLocalError("cannot access local variable 'run_name' where it is not associated with a value")
2023-05-16 10:48:04,335 ERROR   Thread-88 (_run_job):14644 [jupyter.py:notebook_metadata():224] Failed to detect the name of this notebook, you can set it manually with the WANDB_NOTEBOOK_NAME environment variable to enable code saving.
2023-05-16 10:48:11,235 INFO    Thread-88 (_run_job):14644 [wandb_setup.py:_flush():76] Configure stats pid to 14644
2023-05-16 10:48:11,235 INFO    Thread-88 (_run_job):14644 [wandb_setup.py:_flush():76] Loading settings from C:\Users\gaura\.config\wandb\settings
2023-05-16 10:48:11,236 INFO    Thread-88 (_run_job):14644 [wandb_setup.py:_flush():76] Loading settings from c:\Users\gaura\PycharmProjects\scientificProject\wandb\settings
2023-05-16 10:48:11,236 INFO    Thread-88 (_run_job):14644 [wandb_setup.py:_flush():76] Loading settings from environment variables: {'entity': 'cs22m045', 'project': 'aksharantar_without_attention_1', 'root_dir': 'c:\\Users\\gaura\\PycharmProjects\\scientificProject', 'run_id': 'mic4db9k', 'sweep_param_path': 'c:\\Users\\gaura\\PycharmProjects\\scientificProject\\wandb\\sweep-hh3vahjz\\config-mic4db9k.yaml', 'sweep_id': 'hh3vahjz'}
2023-05-16 10:48:11,245 INFO    Thread-88 (_run_job):14644 [wandb_setup.py:_flush():76] Applying setup settings: {'_disable_service': False}
2023-05-16 10:48:11,245 INFO    Thread-88 (_run_job):14644 [wandb_setup.py:_flush():76] Inferring run settings from compute environment: {'program': '<python with no main file>'}
2023-05-16 10:48:11,246 INFO    Thread-88 (_run_job):14644 [wandb_init.py:_log_setup():506] Logging user logs to c:\Users\gaura\PycharmProjects\scientificProject\wandb\run-20230516_104811-mic4db9k\logs\debug.log
2023-05-16 10:48:11,246 INFO    Thread-88 (_run_job):14644 [wandb_init.py:_log_setup():507] Logging internal logs to c:\Users\gaura\PycharmProjects\scientificProject\wandb\run-20230516_104811-mic4db9k\logs\debug-internal.log
2023-05-16 10:48:11,246 INFO    Thread-88 (_run_job):14644 [wandb_init.py:_jupyter_setup():452] configuring jupyter hooks <wandb.sdk.wandb_init._WandbInit object at 0x000001FF2ED55C90>
2023-05-16 10:48:11,247 INFO    Thread-88 (_run_job):14644 [wandb_init.py:init():546] calling init triggers
2023-05-16 10:48:11,247 INFO    Thread-88 (_run_job):14644 [wandb_init.py:init():552] wandb.init called with sweep_config: {'batch_size': 64, 'bidirectional': False, 'cell_type': 'GRU', 'dec_dropout': 0.3, 'embedding_size': 512, 'enc_dropout': 0.3, 'hidden_size': 256, 'learning_rate': 0.1, 'num_epochs': 20, 'num_layers': 3}
config: {}
2023-05-16 10:48:11,247 INFO    Thread-88 (_run_job):14644 [wandb_init.py:init():602] starting backend
2023-05-16 10:48:11,247 INFO    Thread-88 (_run_job):14644 [wandb_init.py:init():606] setting up manager
2023-05-16 10:48:11,254 INFO    Thread-88 (_run_job):14644 [backend.py:_multiprocessing_setup():106] multiprocessing start_methods=spawn, using: spawn
2023-05-16 10:48:11,266 INFO    Thread-88 (_run_job):14644 [wandb_init.py:init():613] backend started and connected
2023-05-16 10:48:11,283 INFO    Thread-88 (_run_job):14644 [wandb_run.py:_config_callback():1251] config_cb None None {'batch_size': 64, 'bidirectional': False, 'cell_type': 'GRU', 'dec_dropout': 0.3, 'embedding_size': 512, 'enc_dropout': 0.3, 'hidden_size': 256, 'learning_rate': 0.1, 'num_epochs': 20, 'num_layers': 3}
2023-05-16 10:48:11,284 INFO    Thread-88 (_run_job):14644 [wandb_run.py:_label_probe_notebook():1204] probe notebook
2023-05-16 10:48:11,284 INFO    Thread-88 (_run_job):14644 [wandb_run.py:_label_probe_notebook():1214] Unable to probe notebook: 'NoneType' object has no attribute 'get'
2023-05-16 10:48:11,284 INFO    Thread-88 (_run_job):14644 [wandb_init.py:init():701] updated telemetry
2023-05-16 10:48:11,361 INFO    Thread-88 (_run_job):14644 [wandb_init.py:init():741] communicating run to backend with 60.0 second timeout
2023-05-16 10:48:12,496 INFO    Thread-88 (_run_job):14644 [wandb_run.py:_on_init():2133] communicating current version
2023-05-16 10:48:12,574 INFO    Thread-88 (_run_job):14644 [wandb_run.py:_on_init():2142] got version response upgrade_message: "wandb version 0.15.2 is available!  To upgrade, please run:\n $ pip install wandb --upgrade"

2023-05-16 10:48:12,574 INFO    Thread-88 (_run_job):14644 [wandb_init.py:init():789] starting run threads in backend
2023-05-16 10:48:12,857 INFO    Thread-88 (_run_job):14644 [wandb_run.py:_console_start():2114] atexit reg
2023-05-16 10:48:12,858 INFO    Thread-88 (_run_job):14644 [wandb_run.py:_redirect():1969] redirect: 3
2023-05-16 10:48:12,858 INFO    Thread-88 (_run_job):14644 [wandb_run.py:_redirect():2034] Wrapping output streams.
2023-05-16 10:48:12,858 INFO    Thread-88 (_run_job):14644 [wandb_run.py:_redirect():2059] Redirects installed.
2023-05-16 10:48:12,859 INFO    Thread-88 (_run_job):14644 [wandb_init.py:init():831] run started, returning control to user process
2023-05-16 10:48:12,859 INFO    Thread-88 (_run_job):14644 [wandb_run.py:_finish():1854] finishing run cs22m045/aksharantar_without_attention_1/mic4db9k
2023-05-16 10:48:12,860 INFO    Thread-88 (_run_job):14644 [jupyter.py:save_history():445] not saving jupyter history
2023-05-16 10:48:12,860 INFO    Thread-88 (_run_job):14644 [jupyter.py:save_ipynb():373] not saving jupyter notebook
2023-05-16 10:48:12,860 INFO    Thread-88 (_run_job):14644 [wandb_init.py:_jupyter_teardown():434] cleaning up jupyter logic
2023-05-16 10:48:12,860 INFO    Thread-88 (_run_job):14644 [wandb_run.py:_atexit_cleanup():2083] got exitcode: 1
2023-05-16 10:48:12,860 INFO    Thread-88 (_run_job):14644 [wandb_run.py:_restore():2066] restore
2023-05-16 10:48:12,861 INFO    Thread-88 (_run_job):14644 [wandb_run.py:_restore():2072] restore done
2023-05-16 10:48:18,561 INFO    Thread-88 (_run_job):14644 [wandb_run.py:_footer_history_summary_info():3422] rendering history
2023-05-16 10:48:18,562 INFO    Thread-88 (_run_job):14644 [wandb_run.py:_footer_history_summary_info():3454] rendering summary
2023-05-16 10:48:18,576 INFO    Thread-88 (_run_job):14644 [wandb_run.py:_footer_sync_info():3380] logging synced files
2023-05-16 10:48:18,586 ERROR   MainThread:14644 [pyagent.py:_run_jobs_from_queue():226] Run mic4db9k errored: UnboundLocalError("cannot access local variable 'run_name' where it is not associated with a value")
2023-05-16 10:48:21,069 ERROR   Thread-91 (_run_job):14644 [jupyter.py:notebook_metadata():224] Failed to detect the name of this notebook, you can set it manually with the WANDB_NOTEBOOK_NAME environment variable to enable code saving.
2023-05-16 10:48:25,624 INFO    Thread-91 (_run_job):14644 [wandb_setup.py:_flush():76] Configure stats pid to 14644
2023-05-16 10:48:25,624 INFO    Thread-91 (_run_job):14644 [wandb_setup.py:_flush():76] Loading settings from C:\Users\gaura\.config\wandb\settings
2023-05-16 10:48:25,624 INFO    Thread-91 (_run_job):14644 [wandb_setup.py:_flush():76] Loading settings from c:\Users\gaura\PycharmProjects\scientificProject\wandb\settings
2023-05-16 10:48:25,625 INFO    Thread-91 (_run_job):14644 [wandb_setup.py:_flush():76] Loading settings from environment variables: {'entity': 'cs22m045', 'project': 'aksharantar_without_attention_1', 'root_dir': 'c:\\Users\\gaura\\PycharmProjects\\scientificProject', 'run_id': '1v2gfgp6', 'sweep_param_path': 'c:\\Users\\gaura\\PycharmProjects\\scientificProject\\wandb\\sweep-hh3vahjz\\config-1v2gfgp6.yaml', 'sweep_id': 'hh3vahjz'}
2023-05-16 10:48:25,626 INFO    Thread-91 (_run_job):14644 [wandb_setup.py:_flush():76] Applying setup settings: {'_disable_service': False}
2023-05-16 10:48:25,626 INFO    Thread-91 (_run_job):14644 [wandb_setup.py:_flush():76] Inferring run settings from compute environment: {'program': '<python with no main file>'}
2023-05-16 10:48:25,627 INFO    Thread-91 (_run_job):14644 [wandb_init.py:_log_setup():506] Logging user logs to c:\Users\gaura\PycharmProjects\scientificProject\wandb\run-20230516_104825-1v2gfgp6\logs\debug.log
2023-05-16 10:48:25,627 INFO    Thread-91 (_run_job):14644 [wandb_init.py:_log_setup():507] Logging internal logs to c:\Users\gaura\PycharmProjects\scientificProject\wandb\run-20230516_104825-1v2gfgp6\logs\debug-internal.log
2023-05-16 10:48:25,627 INFO    Thread-91 (_run_job):14644 [wandb_init.py:_jupyter_setup():452] configuring jupyter hooks <wandb.sdk.wandb_init._WandbInit object at 0x000001FF2DE9E050>
2023-05-16 10:48:25,628 INFO    Thread-91 (_run_job):14644 [wandb_init.py:init():546] calling init triggers
2023-05-16 10:48:25,628 INFO    Thread-91 (_run_job):14644 [wandb_init.py:init():552] wandb.init called with sweep_config: {'batch_size': 128, 'bidirectional': False, 'cell_type': 'RNN', 'dec_dropout': 0.5, 'embedding_size': 256, 'enc_dropout': 0.5, 'hidden_size': 512, 'learning_rate': 0.1, 'num_epochs': 20, 'num_layers': 1}
config: {}
2023-05-16 10:48:25,628 INFO    Thread-91 (_run_job):14644 [wandb_init.py:init():602] starting backend
2023-05-16 10:48:25,628 INFO    Thread-91 (_run_job):14644 [wandb_init.py:init():606] setting up manager
2023-05-16 10:48:25,646 INFO    Thread-91 (_run_job):14644 [backend.py:_multiprocessing_setup():106] multiprocessing start_methods=spawn, using: spawn
2023-05-16 10:48:25,690 INFO    Thread-91 (_run_job):14644 [wandb_init.py:init():613] backend started and connected
2023-05-16 10:48:25,715 INFO    Thread-91 (_run_job):14644 [wandb_run.py:_config_callback():1251] config_cb None None {'batch_size': 128, 'bidirectional': False, 'cell_type': 'RNN', 'dec_dropout': 0.5, 'embedding_size': 256, 'enc_dropout': 0.5, 'hidden_size': 512, 'learning_rate': 0.1, 'num_epochs': 20, 'num_layers': 1}
2023-05-16 10:48:25,716 INFO    Thread-91 (_run_job):14644 [wandb_run.py:_label_probe_notebook():1204] probe notebook
2023-05-16 10:48:25,716 INFO    Thread-91 (_run_job):14644 [wandb_run.py:_label_probe_notebook():1214] Unable to probe notebook: 'NoneType' object has no attribute 'get'
2023-05-16 10:48:25,716 INFO    Thread-91 (_run_job):14644 [wandb_init.py:init():701] updated telemetry
2023-05-16 10:48:25,963 INFO    Thread-91 (_run_job):14644 [wandb_init.py:init():741] communicating run to backend with 60.0 second timeout
2023-05-16 10:48:26,800 INFO    Thread-91 (_run_job):14644 [wandb_run.py:_on_init():2133] communicating current version
2023-05-16 10:48:26,913 INFO    Thread-91 (_run_job):14644 [wandb_run.py:_on_init():2142] got version response upgrade_message: "wandb version 0.15.2 is available!  To upgrade, please run:\n $ pip install wandb --upgrade"

2023-05-16 10:48:26,914 INFO    Thread-91 (_run_job):14644 [wandb_init.py:init():789] starting run threads in backend
2023-05-16 10:48:27,398 INFO    Thread-91 (_run_job):14644 [wandb_run.py:_console_start():2114] atexit reg
2023-05-16 10:48:27,398 INFO    Thread-91 (_run_job):14644 [wandb_run.py:_redirect():1969] redirect: 3
2023-05-16 10:48:27,399 INFO    Thread-91 (_run_job):14644 [wandb_run.py:_redirect():2034] Wrapping output streams.
2023-05-16 10:48:27,408 INFO    Thread-91 (_run_job):14644 [wandb_run.py:_redirect():2059] Redirects installed.
2023-05-16 10:48:27,409 INFO    Thread-91 (_run_job):14644 [wandb_init.py:init():831] run started, returning control to user process
2023-05-16 10:48:27,410 INFO    Thread-91 (_run_job):14644 [wandb_run.py:_finish():1854] finishing run cs22m045/aksharantar_without_attention_1/1v2gfgp6
2023-05-16 10:48:27,411 INFO    Thread-91 (_run_job):14644 [jupyter.py:save_history():445] not saving jupyter history
2023-05-16 10:48:27,411 INFO    Thread-91 (_run_job):14644 [jupyter.py:save_ipynb():373] not saving jupyter notebook
2023-05-16 10:48:27,411 INFO    Thread-91 (_run_job):14644 [wandb_init.py:_jupyter_teardown():434] cleaning up jupyter logic
2023-05-16 10:48:27,411 INFO    Thread-91 (_run_job):14644 [wandb_run.py:_atexit_cleanup():2083] got exitcode: 1
2023-05-16 10:48:27,411 INFO    Thread-91 (_run_job):14644 [wandb_run.py:_restore():2066] restore
2023-05-16 10:48:27,412 INFO    Thread-91 (_run_job):14644 [wandb_run.py:_restore():2072] restore done
2023-05-16 10:48:33,323 INFO    Thread-91 (_run_job):14644 [wandb_run.py:_footer_history_summary_info():3422] rendering history
2023-05-16 10:48:33,323 INFO    Thread-91 (_run_job):14644 [wandb_run.py:_footer_history_summary_info():3454] rendering summary
2023-05-16 10:48:33,332 INFO    Thread-91 (_run_job):14644 [wandb_run.py:_footer_sync_info():3380] logging synced files
2023-05-16 10:48:33,340 ERROR   MainThread:14644 [pyagent.py:_run_jobs_from_queue():226] Run 1v2gfgp6 errored: UnboundLocalError("cannot access local variable 'run_name' where it is not associated with a value")
2023-05-16 10:48:33,348 ERROR   MainThread:14644 [pyagent.py:_run_jobs_from_queue():237] Detected 3 failed runs in the first 60 seconds, killing sweep.
2023-05-16 10:52:09,316 INFO    MainThread:14644 [retry.py:__call__():172] Retry attempt failed:
Traceback (most recent call last):
  File "C:\Users\gaura\AppData\Roaming\Python\Python311\site-packages\urllib3\connection.py", line 174, in _new_conn
    conn = connection.create_connection(
           ^^^^^^^^^^^^^^^^^^^^^^^^^^^^^
  File "C:\Users\gaura\AppData\Roaming\Python\Python311\site-packages\urllib3\util\connection.py", line 72, in create_connection
    for res in socket.getaddrinfo(host, port, family, socket.SOCK_STREAM):
               ^^^^^^^^^^^^^^^^^^^^^^^^^^^^^^^^^^^^^^^^^^^^^^^^^^^^^^^^^^
  File "c:\Program Files\Python311\Lib\socket.py", line 962, in getaddrinfo
    for res in _socket.getaddrinfo(host, port, family, type, proto, flags):
               ^^^^^^^^^^^^^^^^^^^^^^^^^^^^^^^^^^^^^^^^^^^^^^^^^^^^^^^^^^^
socket.gaierror: [Errno 11001] getaddrinfo failed

During handling of the above exception, another exception occurred:

Traceback (most recent call last):
  File "C:\Users\gaura\AppData\Roaming\Python\Python311\site-packages\urllib3\connectionpool.py", line 703, in urlopen
    httplib_response = self._make_request(
                       ^^^^^^^^^^^^^^^^^^^
  File "C:\Users\gaura\AppData\Roaming\Python\Python311\site-packages\urllib3\connectionpool.py", line 386, in _make_request
    self._validate_conn(conn)
  File "C:\Users\gaura\AppData\Roaming\Python\Python311\site-packages\urllib3\connectionpool.py", line 1042, in _validate_conn
    conn.connect()
  File "C:\Users\gaura\AppData\Roaming\Python\Python311\site-packages\urllib3\connection.py", line 363, in connect
    self.sock = conn = self._new_conn()
                       ^^^^^^^^^^^^^^^^
  File "C:\Users\gaura\AppData\Roaming\Python\Python311\site-packages\urllib3\connection.py", line 186, in _new_conn
    raise NewConnectionError(
urllib3.exceptions.NewConnectionError: <urllib3.connection.HTTPSConnection object at 0x000001FF2D5717D0>: Failed to establish a new connection: [Errno 11001] getaddrinfo failed

During handling of the above exception, another exception occurred:

Traceback (most recent call last):
  File "C:\Users\gaura\AppData\Roaming\Python\Python311\site-packages\requests\adapters.py", line 489, in send
    resp = conn.urlopen(
           ^^^^^^^^^^^^^
  File "C:\Users\gaura\AppData\Roaming\Python\Python311\site-packages\urllib3\connectionpool.py", line 787, in urlopen
    retries = retries.increment(
              ^^^^^^^^^^^^^^^^^^
  File "C:\Users\gaura\AppData\Roaming\Python\Python311\site-packages\urllib3\util\retry.py", line 592, in increment
    raise MaxRetryError(_pool, url, error or ResponseError(cause))
urllib3.exceptions.MaxRetryError: HTTPSConnectionPool(host='api.wandb.ai', port=443): Max retries exceeded with url: /graphql (Caused by NewConnectionError('<urllib3.connection.HTTPSConnection object at 0x000001FF2D5717D0>: Failed to establish a new connection: [Errno 11001] getaddrinfo failed'))

During handling of the above exception, another exception occurred:

Traceback (most recent call last):
  File "C:\Users\gaura\AppData\Roaming\Python\Python311\site-packages\wandb\sdk\lib\retry.py", line 131, in __call__
    result = self._call_fn(*args, **kwargs)
             ^^^^^^^^^^^^^^^^^^^^^^^^^^^^^^
  File "C:\Users\gaura\AppData\Roaming\Python\Python311\site-packages\wandb\sdk\internal\internal_api.py", line 243, in execute
    return self.client.execute(*args, **kwargs)  # type: ignore
           ^^^^^^^^^^^^^^^^^^^^^^^^^^^^^^^^^^^^
  File "C:\Users\gaura\AppData\Roaming\Python\Python311\site-packages\wandb\vendor\gql-0.2.0\wandb_gql\client.py", line 52, in execute
    result = self._get_result(document, *args, **kwargs)
             ^^^^^^^^^^^^^^^^^^^^^^^^^^^^^^^^^^^^^^^^^^^
  File "C:\Users\gaura\AppData\Roaming\Python\Python311\site-packages\wandb\vendor\gql-0.2.0\wandb_gql\client.py", line 60, in _get_result
    return self.transport.execute(document, *args, **kwargs)
           ^^^^^^^^^^^^^^^^^^^^^^^^^^^^^^^^^^^^^^^^^^^^^^^^^
  File "C:\Users\gaura\AppData\Roaming\Python\Python311\site-packages\wandb\vendor\gql-0.2.0\wandb_gql\transport\requests.py", line 38, in execute
    request = requests.post(self.url, **post_args)
              ^^^^^^^^^^^^^^^^^^^^^^^^^^^^^^^^^^^^
  File "C:\Users\gaura\AppData\Roaming\Python\Python311\site-packages\requests\api.py", line 115, in post
    return request("post", url, data=data, json=json, **kwargs)
           ^^^^^^^^^^^^^^^^^^^^^^^^^^^^^^^^^^^^^^^^^^^^^^^^^^^^
  File "C:\Users\gaura\AppData\Roaming\Python\Python311\site-packages\requests\api.py", line 59, in request
    return session.request(method=method, url=url, **kwargs)
           ^^^^^^^^^^^^^^^^^^^^^^^^^^^^^^^^^^^^^^^^^^^^^^^^^
  File "C:\Users\gaura\AppData\Roaming\Python\Python311\site-packages\requests\sessions.py", line 587, in request
    resp = self.send(prep, **send_kwargs)
           ^^^^^^^^^^^^^^^^^^^^^^^^^^^^^^
  File "C:\Users\gaura\AppData\Roaming\Python\Python311\site-packages\requests\sessions.py", line 701, in send
    r = adapter.send(request, **kwargs)
        ^^^^^^^^^^^^^^^^^^^^^^^^^^^^^^^
  File "C:\Users\gaura\AppData\Roaming\Python\Python311\site-packages\requests\adapters.py", line 565, in send
    raise ConnectionError(e, request=request)
requests.exceptions.ConnectionError: HTTPSConnectionPool(host='api.wandb.ai', port=443): Max retries exceeded with url: /graphql (Caused by NewConnectionError('<urllib3.connection.HTTPSConnection object at 0x000001FF2D5717D0>: Failed to establish a new connection: [Errno 11001] getaddrinfo failed'))
